<?xml version="1.0" ?>
<robot name="mecanum3" xmlns:xacro="http://www.ros.org/wiki/xacro">

<xacro:include filename="$(find mecanumrover_description)/urdf/materials.xacro" />
<!-- <xacro:include filename="$(find mecanumrover_description)/urdf/mecanum3.trans" /> -->
<!-- <xacro:include filename="$(find mecanumrover_description)/urdf/mecanum3.gazebo" /> -->
<!-- OPTION: LRF TG30 -->
<!-- <xacro:include filename="$(find vs_rover_options_description)/urdf/lrf/tg30_mecanum3.xacro" /> -->


<link name="base_footprint" />

<joint name="base_joint" type="fixed">
  <parent link="base_footprint"/>
  <child link="base_link" />
  <origin xyz="0 0 0" rpy="0 0 ${radians(-90)}"/>
</joint>

<link name="base_link">
  <inertial>
    <origin xyz="8.039076182406018e-05 -0.001484050423595346 0.11040223412633365" rpy="0 0 0"/>
    <mass value="51.54953324093924"/>
    <inertia ixx="0.451406" iyy="0.211369" izz="0.557559" ixy="0.000784" iyz="0.000199" ixz="-0.000134"/>
  </inertial>
  <visual>
    <origin xyz="0 0 0" rpy="0 0 0"/>
    <geometry>
      <mesh filename="package://mecanumrover_description/meshes/base_link.stl" scale="0.001 0.001 0.001"/>
    </geometry>
    <material name="silver"/>
  </visual>
  <collision>
    <origin xyz="0 0 0" rpy="0 0 0"/>
    <geometry>
      <mesh filename="package://mecanumrover_description/meshes/base_link.stl" scale="0.001 0.001 0.001"/>
    </geometry>
  </collision>
</link>

<link name="front_left_wheel_1">
  <inertial>
    <origin xyz="-0.03247844667661433 -1.7208456881689926e-15 1.3877787807814457e-17" rpy="0 0 0"/>
    <mass value="6.210672529256712"/>
    <inertia ixx="0.017207" iyy="0.009618" izz="0.009618" ixy="0.0" iyz="0.0" ixz="-0.0"/>
  </inertial>
  <visual>
    <origin xyz="0.0875 -0.12 -0.076" rpy="0 0 0"/>
    <geometry>
      <mesh filename="package://mecanumrover_description/meshes/front_left_wheel_1.stl" scale="0.001 0.001 0.001"/>
    </geometry>
    <material name="dark_grey"/>
  </visual>
  <collision>
    <origin xyz="0.0875 -0.12 -0.076" rpy="0 0 0"/>
    <geometry>
      <mesh filename="package://mecanumrover_description/meshes/front_left_wheel_1.stl" scale="0.001 0.001 0.001"/>
    </geometry>
  </collision>
</link>

<link name="front_right_wheel_1">
  <inertial>
    <origin xyz="0.032478446676614314 -3.7470027081099033e-16 1.3877787807814457e-17" rpy="0 0 0"/>
    <mass value="6.210672529256714"/>
    <inertia ixx="0.017207" iyy="0.009618" izz="0.009618" ixy="-0.0" iyz="0.0" ixz="0.0"/>
  </inertial>
  <visual>
    <origin xyz="-0.0875 -0.12 -0.076" rpy="0 0 0"/>
    <geometry>
      <mesh filename="package://mecanumrover_description/meshes/front_right_wheel_1.stl" scale="0.001 0.001 0.001"/>
    </geometry>
    <material name="dark_grey"/>
  </visual>
  <collision>
    <origin xyz="-0.0875 -0.12 -0.076" rpy="0 0 0"/>
    <geometry>
      <mesh filename="package://mecanumrover_description/meshes/front_right_wheel_1.stl" scale="0.001 0.001 0.001"/>
    </geometry>
  </collision>
</link>

<link name="back_right_wheel_1">
  <inertial>
    <origin xyz="0.03247844667661433 1.7208456881689926e-15 1.3877787807814457e-17" rpy="0 0 0"/>
    <mass value="6.210672529256712"/>
    <inertia ixx="0.017207" iyy="0.009618" izz="0.009618" ixy="0.0" iyz="0.0" ixz="0.0"/>
  </inertial>
  <visual>
    <origin xyz="-0.0875 0.12 -0.076" rpy="0 0 0"/>
    <geometry>
      <mesh filename="package://mecanumrover_description/meshes/back_right_wheel_1.stl" scale="0.001 0.001 0.001"/>
    </geometry>
    <material name="dark_grey"/>
  </visual>
  <collision>
    <origin xyz="-0.0875 0.12 -0.076" rpy="0 0 0"/>
    <geometry>
      <mesh filename="package://mecanumrover_description/meshes/back_right_wheel_1.stl" scale="0.001 0.001 0.001"/>
    </geometry>
  </collision>
</link>

<link name="back_left_wheel_1">
  <inertial>
    <origin xyz="-0.03247844667661433 3.7470027081099033e-16 0.0" rpy="0 0 0"/>
    <mass value="6.210672529256715"/>
    <inertia ixx="0.017207" iyy="0.009618" izz="0.009618" ixy="-0.0" iyz="0.0" ixz="0.0"/>
  </inertial>
  <visual>
    <origin xyz="0.0875 0.12 -0.076" rpy="0 0 0"/>
    <geometry>
      <mesh filename="package://mecanumrover_description/meshes/back_left_wheel_1.stl" scale="0.001 0.001 0.001"/>
    </geometry>
    <material name="dark_grey"/>
  </visual>
  <collision>
    <origin xyz="0.0875 0.12 -0.076" rpy="0 0 0"/>
    <geometry>
      <mesh filename="package://mecanumrover_description/meshes/back_left_wheel_1.stl" scale="0.001 0.001 0.001"/>
    </geometry>
  </collision>
</link>

<joint name="front_left_joint" type="continuous">
  <origin xyz="-0.0875 0.12 0.076" rpy="0 0 0"/>
  <parent link="base_link"/>
  <child link="front_left_wheel_1"/>
  <axis xyz="-1.0 0.0 0.0"/>
</joint>

<joint name="front_right_joint" type="continuous">
  <origin xyz="0.0875 0.12 0.076" rpy="0 0 0"/>
  <parent link="base_link"/>
  <child link="front_right_wheel_1"/>
  <axis xyz="1.0 0.0 0.0"/>
</joint>

<joint name="back_right_joint" type="continuous">
  <origin xyz="0.0875 -0.12 0.076" rpy="0 0 0"/>
  <parent link="base_link"/>
  <child link="back_right_wheel_1"/>
  <axis xyz="1.0 0.0 0.0"/>
</joint>

<joint name="back_left_joint" type="continuous">
  <origin xyz="-0.0875 -0.12 0.076" rpy="0 0 0"/>
  <parent link="base_link"/>
  <child link="back_left_wheel_1"/>
  <axis xyz="-1.0 0.0 0.0"/>
</joint>

</robot>
